Workbook

Sheet Synthèse agences R
D3: Total (2023) | E3: Fermeture | H3: Autonomie
C4: Synthèse Résolution | E4: Cession d'actif | F4: Suppression | G4: Internali-sation | H4: EPIC - musée & patrimoine | I4: EPIC - enseignement & recherche | J4: Autorité indépendante
C5: Agences Etat | D5: =SUM(D6:D7,D8:D9) -> 1104 | E5: =SUM(E6:E9) -> 78 | F5: =SUM(F6:F9) -> 668 | G5: =SUM(G6:G9) -> 55 | H5: =SUM(H6:H9) -> 40 | I5: =SUM(I6:I9) -> 258 | J5: =SUM(J6:J9) -> 5
C6: Opérateurs (PLF) | D6: ='Opérateurs R'!F3 -> 434 | E6: ='Opérateurs R'!N3 -> 15 | F6: ='Opérateurs R'!O3 -> 123 | G6: ='Opérateurs R'!R3 -> 34 | H6: ='Opérateurs R'!P3 -> 36 | I6: ='Opérateurs R'!Q3 -> 226
C7: Organismes hors PLF | D7: ='ODAC-ODAL R'!B4-'ODAC-ODAL R'!C4 -> 328 | E7: ='ODAC-ODAL R'!D4 -> 63 | F7: ='ODAC-ODAL R'!E4 -> 217 | G7: ='ODAC-ODAL R'!H4 -> 12 | H7: ='ODAC-ODAL R'!F4 -> 4 | I7: ='ODAC-ODAL R'!G4 -> 32
C8: Autorités indépendantes | D8: ='ODAC-ODAL R'!B752-'ODAC-ODAL R'!C752 -> 24 | F8: ='ODAC-ODAL R'!E752 -> 10 | G8: ='ODAC-ODAL R'!H752 -> 9 | J8: ='ODAC-ODAL R'!I752 -> 5
C9: Commissions | D9: 318 | F9: =D9 -> 318
C10: Agences locales | D10: =D11 -> 23264 | E10: =E11 -> 347 | F10: =F11 -> 13481 | G10: =G11 -> 296 | I10: =I11 -> 9140
C11: Organismes hors PLF | D11: ='ODAC-ODAL R'!B726-'ODAC-ODAL R'!C726 -> 23264 | E11: ='ODAC-ODAL R'!D726 -> 347 | F11: ='ODAC-ODAL R'!E726 -> 13481 | G11: ='ODAC-ODAL R'!H726 -> 296 | I11: ='ODAC-ODAL R'!G726 -> 9140
C12: Total agences | D12: =D5+D10 -> 24368 | E12: =E5+E10 -> 425 | F12: =F5+F10 -> 14149 | G12: =G5+G10 -> 351 | H12: =H5+H10 -> 40 | I12: =I5+I10 -> 9398 | J12: =J5+J10 -> 5

Sheet Opérateurs R
A2: M | B2: Mission | C2: Pg | D2: Programme | E2: Intitulé de l'opérateur | F2: Nb/cat. | G2: LFI 2025 - ETPT total | H2: LFI 2025 – ETPT sous plafond | I2: LFI 2025 – ETPT hors plafond | J2: PLF 2026 - ETPT total | K2: PLF 2026 – ETPT sous plafond | L2: PLF 2026 – ETPT hors plafond | N2: Vente | O2: Suppression | P2: EPIC - musée | Q2: EPIC - études | R2: Internalisation
E3: Total général | F3: =SUM(F5:F184) -> 434 | N3: =SUMIFS($F5:$F184,N5:N184,"X") -> 15 | O3: =SUMIFS($F5:$F184,O5:O184,"X") -> 123 | P3: =SUMIFS($F5:$F184,P5:P184,"X") -> 36 | Q3: =SUMIFS($F5:$F184,Q5:Q184,"X") -> 226 | R3: =SUMIFS($F5:$F184,R5:R184,"X") -> 34
G4: =H4+I4 -> 479514 | H4: 402456 | I4: 77058 | J4: =K4+L4 -> 478026 | K4: 401310 | L4: 76716 | N4: =SUMIFS($G5:$G184,N5:N184,"X") -> 10476 | O4: =SUMIFS($G5:$G184,O5:O184,"X") -> 99885 | P4: =SUMIFS($G5:$G184,P5:P184,"X") -> 25039 | Q4: =SUMIFS($G5:$G184,Q5:Q184,"X") -> 326723 | R4: =SUMIFS($G5:$G184,R5:R184,"X") -> 17391 | S4: ETP
A5: =_xlfn.XLOOKUP(C5,'Annexe Etat'!$I$2:$I$164,'Annexe Etat'!$H$2:$H$164) -> RA | B5: =_xlfn.XLOOKUP(A5,'Annexe Etat'!$A$2:$A$164,'Annexe Etat'!$B$2:$B$164) -> Recherche et enseignement supérieur | C5: 172 | D5: =_xlfn.XLOOKUP(C5,'Annexe Etat'!$I$2:$I$164,'Annexe Etat'!$J$2:$J$164) -> Recherches scientifiques et technologiques pluridisciplinaires | E5: Académie des technologies | F5: 1 | G5: =H5+I5 -> 10 | H5: 9 | I5: 1 | J5: =K5+L5 -> 9 | K5: 9 | L5: 0 | O5: X
A6: =_xlfn.XLOOKUP(C6,'Annexe Etat'!$I$2:$I$164,'Annexe Etat'!$H$2:$H$164) -> AB | B6: =_xlfn.XLOOKUP(A6,'Annexe Etat'!$A$2:$A$164,'Annexe Etat'!$B$2:$B$164) -> Administration générale et territoriale de l'État | C6: 216 | D6: =_xlfn.XLOOKUP(C6,'Annexe Etat'!$I$2:$I$164,'Annexe Etat'!$J$2:$J$164) -> Conduite et pilotage des politiques de l'intérieur | E6: ACMOSS - Agence des Communications Mobiles Opérationnelles de Sécurité et de Secours | F6: 1 | G6: =H6+I6 -> 81 | H6: 76 | I6: 5 | J6: =K6+L6 -> 101 | K6: 98 | L6: 3 | R6: X
A7: =_xlfn.XLOOKUP(C7,'Annexe Etat'!$I$2:$I$164,'Annexe Etat'!$H$2:$H$164) -> TA | B7: =_xlfn.XLOOKUP(A7,'Annexe Etat'!$A$2:$A$164,'Annexe Etat'!$B$2:$B$164) -> Écologie, développement et mobilité durables | C7: 181 | D7: =_xlfn.XLOOKUP(C7,'Annexe Etat'!$I$2:$I$164,'Annexe Etat'!$J$2:$J$164) -> Prévention des risques | E7: ADEME - Agence de l'environnement et de la maîtrise de l'énergie | F7: 1 | G7: =H7+I7 -> 1334 | H7: 1069 | I7: 265 | J7: =K7+L7 -> 1330 | K7: 1070 | L7: 260 | O7: X
A8: =_xlfn.XLOOKUP(C8,'Annexe Etat'!$I$2:$I$164,'Annexe Etat'!$H$2:$H$164) -> AA | B8: =_xlfn.XLOOKUP(A8,'Annexe Etat'!$A$2:$A$164,'Annexe Etat'!$B$2:$B$164) -> Action extérieure de l'État | C8: 185 | D8: =_xlfn.XLOOKUP(C8,'Annexe Etat'!$I$2:$I$164,'Annexe Etat'!$J$2:$J$164) -> Diplomatie culturelle et d'influence | E8: AEFE - Agence pour l'enseignement français à l'étranger | F8: 1 | G8: =H8+I8 -> 10740 | H8: 5579 | I8: 5161 | J8: =K8+L8 -> 10722 | K8: 5561 | L8: 5161 | Q8: X
A9: =_xlfn.XLOOKUP(C9,'Annexe Etat'!$I$2:$I$164,'Annexe Etat'!$H$2:$H$164) -> TA | B9: =_xlfn.XLOOKUP(A9,'Annexe Etat'!$A$2:$A$164,'Annexe Etat'!$B$2:$B$164) -> Écologie, développement et mobilité durables | C9: 203 | D9: =_xlfn.XLOOKUP(C9,'Annexe Etat'!$I$2:$I$164,'Annexe Etat'!$J$2:$J$164) -> Infrastructures et services de transports | E9: AFITF - Agence de financement des infrastructures de transport de France | F9: 1 | G9: =H9+I9 -> 0 | H9: 0 | I9: 0 | J9: =K9+L9 -> 0 | K9: 0 | L9: 0 | O9: X
A10: =_xlfn.XLOOKUP(C10,'Annexe Etat'!$I$2:$I$164,'Annexe Etat'!$H$2:$H$164) -> TB | B10: =_xlfn.XLOOKUP(A10,'Annexe Etat'!$A$2:$A$164,'Annexe Etat'!$B$2:$B$164) -> Travail, emploi et administration des ministères sociaux | C10: 103 | D10: =_xlfn.XLOOKUP(C10,'Annexe Etat'!$I$2:$I$164,'Annexe Etat'!$J$2:$J$164) -> Accompagnement des mutations économiques et développement de l'emploi | E10: AFPA - Agence nationale pour la formation professionnelle des adultes | F10: 1 | G10: =H10+I10 -> 5330 | H10: 5330 | I10: 0 | J10: =K10+L10 -> 4824 | K10: 4824 | L10: 0 | O10: X
A11: =_xlfn.XLOOKUP(C11,'Annexe Etat'!$I$2:$I$164,'Annexe Etat'!$H$2:$H$164) -> CB | B11: =_xlfn.XLOOKUP(A11,'Annexe Etat'!$A$2:$A$164,'Annexe Etat'!$B$2:$B$164) -> Culture | C11: 131 | D11: =_xlfn.XLOOKUP(C11,'Annexe Etat'!$I$2:$I$164,'Annexe Etat'!$J$2:$J$164) -> Création | E11: AFR - Académie de France à Rome | F11: 1 | G11: =H11+I11 -> 47 | H11: 47 | I11: 0 | J11: =K11+L11 -> 47 | K11: 47 | L11: 0 | P11: X
A12: =_xlfn.XLOOKUP(C12,'Annexe Etat'!$I$2:$I$164,'Annexe Etat'!$H$2:$H$164) -> TA | B12: =_xlfn.XLOOKUP(A12,'Annexe Etat'!$A$2:$A$164,'Annexe Etat'!$B$2:$B$164) -> Écologie, développement et mobilité durables | C12: 113 | D12: =_xlfn.XLOOKUP(C12,'Annexe Etat'!$I$2:$I$164,'Annexe Etat'!$J$2:$J$164) -> Paysages, eau et biodiversité | E12: Agences de l'eau | F12: 6 | G12: =H12+I12 -> 1575 | H12: 1551 | I12: 24 | J12: =K12+L12 -> 1562 | K12: 1539 | L12: 23 | O12: X
A13: =_xlfn.XLOOKUP(C13,'Annexe Etat'!$I$2:$I$164,'Annexe Etat'!$H$2:$H$164) -> JA | B13: =_xlfn.XLOOKUP(A13,'Annexe Etat'!$A$2:$A$164,'Annexe Etat'!$B$2:$B$164) -> Justice | C13: 310 | D13: =_xlfn.XLOOKUP(C13,'Annexe Etat'!$I$2:$I$164,'Annexe Etat'!$J$2:$J$164) -> Conduite et pilotage de la politique de la justice | E13: AGRASC - Agence de gestion et de recouvrement des avoirs saisis et confisqués | F13: 1 | G13: =H13+I13 -> 69 | H13: 69 | I13: 0 | J13: =K13+L13 -> 69 | K13: 69 | L13: 0 | R13: X
A14: =_xlfn.XLOOKUP(C14,'Annexe Etat'!$I$2:$I$164,'Annexe Etat'!$H$2:$H$164) -> TB | B14: =_xlfn.XLOOKUP(A14,'Annexe Etat'!$A$2:$A$164,'Annexe Etat'!$B$2:$B$164) -> Travail, emploi et administration des ministères sociaux | C14: 111 | D14: =_xlfn.XLOOKUP(C14,'Annexe Etat'!$I$2:$I$164,'Annexe Etat'!$J$2:$J$164) -> Amélioration de la qualité de l'emploi et des relations du travail | E14: ANACT - Agence nationale pour l'amélioration des conditions de travail | F14: 1 | G14: =H14+I14 -> 290 | H14: 265 | I14: 25 | J14: =K14+L14 -> 290 | K14: 265 | L14: 25 | O14: X
A15: =_xlfn.XLOOKUP(C15,'Annexe Etat'!$I$2:$I$164,'Annexe Etat'!$H$2:$H$164) -> VA | B15: =_xlfn.XLOOKUP(A15,'Annexe Etat'!$A$2:$A$164,'Annexe Etat'!$B$2:$B$164) -> Cohésion des territoires | C15: 135 | D15: =_xlfn.XLOOKUP(C15,'Annexe Etat'!$I$2:$I$164,'Annexe Etat'!$J$2:$J$164) -> Urbanisme, territoires et amélioration de l'habitat | E15: ANAH - Agence nationale de l'habitat | F15: 1 | G15: =H15+I15 -> 285 | H15: 285 | I15: 0 | J15: =K15+L15 -> 287 | K15: 287 | L15: 0 | O15: X
A16: =_xlfn.XLOOKUP(C16,'Annexe Etat'!$I$2:$I$164,'Annexe Etat'!$H$2:$H$164) -> VA | B16: =_xlfn.XLOOKUP(A16,'Annexe Etat'!$A$2:$A$164,'Annexe Etat'!$B$2:$B$164) -> Cohésion des territoires | C16: 135 | D16: =_xlfn.XLOOKUP(C16,'Annexe Etat'!$I$2:$I$164,'Annexe Etat'!$J$2:$J$164) -> Urbanisme, territoires et amélioration de l'habitat | E16: ANCOLS - Agence nationale de contrôle du logement social | F16: 1 | G16: =H16+I16 -> 136 | H16: 136 | I16: 0 | J16: =K16+L16 -> 133 | K16: 133 | L16: 0 | R16: X
A17: =_xlfn.XLOOKUP(C17,'Annexe Etat'!$I$2:$I$164,'Annexe Etat'!$H$2:$H$164) -> VA | B17: =_xlfn.XLOOKUP(A17,'Annexe Etat'!$A$2:$A$164,'Annexe Etat'!$B$2:$B$164) -> Cohésion des territoires | C17: 112 | D17: =_xlfn.XLOOKUP(C17,'Annexe Etat'!$I$2:$I$164,'Annexe Etat'!$J$2:$J$164) -> Impulsion et coordination de la politique d'aménagement du territoire | E17: ANCT - Agence nationale de la cohésion des territoires | F17: 1 | G17: =H17+I17 -> 358 | H17: 350 | I17: 8 | J17: =K17+L17 -> 340 | K17: 320 | L17: 20 | O17: X
A18: =_xlfn.XLOOKUP(C18,'Annexe Etat'!$I$2:$I$164,'Annexe Etat'!$H$2:$H$164) -> TA | B18: =_xlfn.XLOOKUP(A18,'Annexe Etat'!$A$2:$A$164,'Annexe Etat'!$B$2:$B$164) -> Écologie, développement et mobilité durables | C18: 174 | D18: =_xlfn.XLOOKUP(C18,'Annexe Etat'!$I$2:$I$164,'Annexe Etat'!$J$2:$J$164) -> Énergie, climat et après-mines | E18: ANDRA - Agence nationale pour la gestion des déchets radioactifs | F18: 1 | G18: =H18+I18 -> 791 | H18: 263 | I18: 528 | J18: =K18+L18 -> 871 | K18: 260 | L18: 611 | R18: X
A19: =_xlfn.XLOOKUP(C19,'Annexe Etat'!$I$2:$I$164,'Annexe Etat'!$H$2:$H$164) -> DB | B19: =_xlfn.XLOOKUP(A19,'Annexe Etat'!$A$2:$A$164,'Annexe Etat'!$B$2:$B$164) -> Économie | C19: 134 | D19: =_xlfn.XLOOKUP(C19,'Annexe Etat'!$I$2:$I$164,'Annexe Etat'!$J$2:$J$164) -> Développement des entreprises et régulations | E19: ANFr - Agence nationale des fréquences | F19: 1 | G19: =H19+I19 -> 297 | H19: 292 | I19: 5 | J19: =K19+L19 -> 292 | K19: 287 | L19: 5 | R19: X
A20: =_xlfn.XLOOKUP(C20,'Annexe Etat'!$I$2:$I$164,'Annexe Etat'!$H$2:$H$164) -> TA | B20: =_xlfn.XLOOKUP(A20,'Annexe Etat'!$A$2:$A$164,'Annexe Etat'!$B$2:$B$164) -> Écologie, développement et mobilité durables | C20: 174 | D20: =_xlfn.XLOOKUP(C20,'Annexe Etat'!$I$2:$I$164,'Annexe Etat'!$J$2:$J$164) -> Énergie, climat et après-mines | E20: ANGDM - Agence nationale pour la garantie des droits des mineurs | F20: 1 | G20: =H20+I20 -> 113 | H20: 113 | I20: 0 | J20: =K20+L20 -> 112 | K20: 110 | L20: 2 | R20: X
A21: =_xlfn.XLOOKUP(C21,'Annexe Etat'!$I$2:$I$164,'Annexe Etat'!$H$2:$H$164) -> RA | B21: =_xlfn.XLOOKUP(A21,'Annexe Etat'!$A$2:$A$164,'Annexe Etat'!$B$2:$B$164) -> Recherche et enseignement supérieur | C21: 172 | D21: =_xlfn.XLOOKUP(C21,'Annexe Etat'!$I$2:$I$164,'Annexe Etat'!$J$2:$J$164) -> Recherches scientifiques et technologiques pluridisciplinaires | E21: ANR - Agence nationale de la recherche | F21: 1 | G21: =H21+I21 -> 385 | H21: 355 | I21: 30 | J21: =K21+L21 -> 398 | K21: 355 | L21: 43 | R21: X
A22: =_xlfn.XLOOKUP(C22,'Annexe Etat'!$I$2:$I$164,'Annexe Etat'!$H$2:$H$164) -> SF | B22: =_xlfn.XLOOKUP(A22,'Annexe Etat'!$A$2:$A$164,'Annexe Etat'!$B$2:$B$164) -> Sport, jeunesse et vie associative | C22: 219 | D22: =_xlfn.XLOOKUP(C22,'Annexe Etat'!$I$2:$I$164,'Annexe Etat'!$J$2:$J$164) -> Sport | E22: ANS - Agence nationale du sport | F22: 1 | G22: =H22+I22 -> 71 | H22: 71 | I22: 0 | J22: =K22+L22 -> 67 | K22: 67 | L22: 0 | O22: X
A23: =_xlfn.XLOOKUP(C23,'Annexe Etat'!$I$2:$I$164,'Annexe Etat'!$H$2:$H$164) -> SB | B23: =_xlfn.XLOOKUP(A23,'Annexe Etat'!$A$2:$A$164,'Annexe Etat'!$B$2:$B$164) -> Sécurités | C23: 161 | D23: =_xlfn.XLOOKUP(C23,'Annexe Etat'!$I$2:$I$164,'Annexe Etat'!$J$2:$J$164) -> Sécurité civile | E23: ANSC - Agence nationale du numérique de la sécurité civile | F23: 1 | G23: =H23+I23 -> 27 | H23: 23 | I23: 4 | J23: =K23+L23 -> 28 | K23: 23 | L23: 5 | R23: X
A24: =_xlfn.XLOOKUP(C24,'Annexe Etat'!$I$2:$I$164,'Annexe Etat'!$H$2:$H$164) -> AC | B24: =_xlfn.XLOOKUP(A24,'Annexe Etat'!$A$2:$A$164,'Annexe Etat'!$B$2:$B$164) -> Agriculture, alimentation, forêt et affaires rurales | C24: 206 | D24: =_xlfn.XLOOKUP(C24,'Annexe Etat'!$I$2:$I$164,'Annexe Etat'!$J$2:$J$164) -> Sécurité et qualité sanitaires de l'alimentation | E24: ANSES - Agence nationale de sécurité sanitaire, de l'alimentation, de l'environnement et du travail | F24: 1 | G24: =H24+I24 -> 1447 | H24: 1327 | I24: 120 | J24: =K24+L24 -> 1458 | K24: 1317 | L24: 141 | R24: X
A25: =_xlfn.XLOOKUP(C25,'Annexe Etat'!$I$2:$I$164,'Annexe Etat'!$H$2:$H$164) -> YE | B25: =_xlfn.XLOOKUP(A25,'Annexe Etat'!$A$2:$A$164,'Annexe Etat'!$B$2:$B$164) -> Contrôle de la circulation et du stationnement routiers | C25: 753 | D25: =_xlfn.XLOOKUP(C25,'Annexe Etat'!$I$2:$I$164,'Annexe Etat'!$J$2:$J$164) -> Contrôle et modernisation de la politique de la circulation et du stationnement routiers | E25: ANTAI - Agence nationale de traitement automatisé des infractions | F25: 1 | G25: =H25+I25 -> 76 | H25: 61 | I25: 15 | J25: =K25+L25 -> 76 | K25: 61 | L25: 15 | R25: X
A26: =_xlfn.XLOOKUP(C26,'Annexe Etat'!$I$2:$I$164,'Annexe Etat'!$H$2:$H$164) -> AB | B26: =_xlfn.XLOOKUP(A26,'Annexe Etat'!$A$2:$A$164,'Annexe Etat'!$B$2:$B$164) -> Administration générale et territoriale de l'État | C26: 354 | D26: =_xlfn.XLOOKUP(C26,'Annexe Etat'!$I$2:$I$164,'Annexe Etat'!$J$2:$J$164) -> Administration territoriale de l'État | E26: ANTS - Agence nationale des titres sécurisés | F26: 1 | G26: =H26+I26 -> 171 | H26: 163 | I26: 8 | J26: =K26+L26 -> 171 | K26: 163 | L26: 8 | R26: X
A27: =_xlfn.XLOOKUP(C27,'Annexe Etat'!$I$2:$I$164,'Annexe Etat'!$H$2:$H$164) -> JA | B27: =_xlfn.XLOOKUP(A27,'Annexe Etat'!$A$2:$A$164,'Annexe Etat'!$B$2:$B$164) -> Justice | C27: 310 | D27: =_xlfn.XLOOKUP(C27,'Annexe Etat'!$I$2:$I$164,'Annexe Etat'!$J$2:$J$164) -> Conduite et pilotage de la politique de la justice | E27: APIJ - Agence publique pour l'immobilier de la Justice | F27: 1 | G27: =H27+I27 -> 169 | H27: 164 | I27: 5 | J27: =K27+L27 -> 169 | K27: 164 | L27: 5 | O27: X
A28: =_xlfn.XLOOKUP(C28,'Annexe Etat'!$I$2:$I$164,'Annexe Etat'!$H$2:$H$164) -> TB | B28: =_xlfn.XLOOKUP(A28,'Annexe Etat'!$A$2:$A$164,'Annexe Etat'!$B$2:$B$164) -> Travail, emploi et administration des ministères sociaux | C28: 155 | D28: =_xlfn.XLOOKUP(C28,'Annexe Etat'!$I$2:$I$164,'Annexe Etat'!$J$2:$J$164) -> Soutien des ministères sociaux | E28: ARS - Agences régionales de santé | F28: 18 | G28: =H28+I28 -> 8273 | H28: 8273 | I28: 0 | J28: =K28+L28 -> 8114 | K28: 8114 | L28: 0 | O28: X
A29: =_xlfn.XLOOKUP(C29,'Annexe Etat'!$I$2:$I$164,'Annexe Etat'!$H$2:$H$164) -> SF | B29: =_xlfn.XLOOKUP(A29,'Annexe Etat'!$A$2:$A$164,'Annexe Etat'!$B$2:$B$164) -> Sport, jeunesse et vie associative | C29: 163 | D29: =_xlfn.XLOOKUP(C29,'Annexe Etat'!$I$2:$I$164,'Annexe Etat'!$J$2:$J$164) -> Jeunesse et vie associative | E29: ASC - Agence du service civique | F29: 1 | G29: =H29+I29 -> 126 | H29: 69 | I29: 57 | J29: =K29+L29 -> 131 | K29: 69 | L29: 62 | O29: X
A30: =_xlfn.XLOOKUP(C30,'Annexe Etat'!$I$2:$I$164,'Annexe Etat'!$H$2:$H$164) -> AC | B30: =_xlfn.XLOOKUP(A30,'Annexe Etat'!$A$2:$A$164,'Annexe Etat'!$B$2:$B$164) -> Agriculture, alimentation, forêt et affaires rurales | C30: 149 | D30: =_xlfn.XLOOKUP(C30,'Annexe Etat'!$I$2:$I$164,'Annexe Etat'!$J$2:$J$164) -> Compétitivité et durabilité de l'agriculture, de l'agroalimentaire et de la forêt | E30: ASP - Agence de services et de paiement | F30: 1 | G30: =H30+I30 -> 2027 | H30: 1786 | I30: 241 | J30: =K30+L30 -> 2063 | K30: 1773 | L30: 290 | R30: X
A31: =_xlfn.XLOOKUP(C31,'Annexe Etat'!$I$2:$I$164,'Annexe Etat'!$H$2:$H$164) -> RA | B31: =_xlfn.XLOOKUP(A31,'Annexe Etat'!$A$2:$A$164,'Annexe Etat'!$B$2:$B$164) -> Recherche et enseignement supérieur | C31: 142 | D31: =_xlfn.XLOOKUP(C31,'Annexe Etat'!$I$2:$I$164,'Annexe Etat'!$J$2:$J$164) -> Enseignement supérieur et recherche agricoles | E31: Associations de coordination technique agricole et des industries agroalimentaires | F31: 2 | G31: =H31+I31 -> 0 | H31: 0 | I31: 0 | J31: =K31+L31 -> 0 | K31: 0 | L31: 0 | O31: X
A32: =_xlfn.XLOOKUP(C32,'Annexe Etat'!$I$2:$I$164,'Annexe Etat'!$H$2:$H$164) -> DB | B32: =_xlfn.XLOOKUP(A32,'Annexe Etat'!$A$2:$A$164,'Annexe Etat'!$B$2:$B$164) -> Économie | C32: 134 | D32: =_xlfn.XLOOKUP(C32,'Annexe Etat'!$I$2:$I$164,'Annexe Etat'!$J$2:$J$164) -> Développement des entreprises et régulations | E32: Atout-France | F32: 1 | G32: =H32+I32 -> 277 | H32: 237 | I32: 40 | J32: =K32+L32 -> 230 | K32: 215 | L32: 15 | O32: X
A33: =_xlfn.XLOOKUP(C33,'Annexe Etat'!$I$2:$I$164,'Annexe Etat'!$H$2:$H$164) -> RA | B33: =_xlfn.XLOOKUP(A33,'Annexe Etat'!$A$2:$A$164,'Annexe Etat'!$B$2:$B$164) -> Recherche et enseignement supérieur | C33: 150 | D33: =_xlfn.XLOOKUP(C33,'Annexe Etat'!$I$2:$I$164,'Annexe Etat'!$J$2:$J$164) -> Formations supérieures et recherche universitaire | E33: Autres opérateurs d'enseignement supérieur et de recherche | F33: 37 | G33: =H33+I33 -> 14747 | H33: 11088 | I33: 3659 | J33: =K33+L33 -> 14844 | K33: 11088 | L33: 3756 | Q33: X
A34: =_xlfn.XLOOKUP(C34,'Annexe Etat'!$I$2:$I$164,'Annexe Etat'!$H$2:$H$164) -> MA | B34: =_xlfn.XLOOKUP(A34,'Annexe Etat'!$A$2:$A$164,'Annexe Etat'!$B$2:$B$164) -> Médias, livre et industries culturelles | C34: 334 | D34: =_xlfn.XLOOKUP(C34,'Annexe Etat'!$I$2:$I$164,'Annexe Etat'!$J$2:$J$164) -> Livre et industries culturelles | E34: BnF - Bibliothèque nationale de France | F34: 1 | G34: =H34+I34 -> 2215 | H34: 2202 | I34: 13 | J34: =K34+L34 -> 2195 | K34: 2195 | L34: 0 | P34: X
A35: =_xlfn.XLOOKUP(C35,'Annexe Etat'!$I$2:$I$164,'Annexe Etat'!$H$2:$H$164) -> MA | B35: =_xlfn.XLOOKUP(A35,'Annexe Etat'!$A$2:$A$164,'Annexe Etat'!$B$2:$B$164) -> Médias, livre et industries culturelles | C35: 334 | D35: =_xlfn.XLOOKUP(C35,'Annexe Etat'!$I$2:$I$164,'Annexe Etat'!$J$2:$J$164) -> Livre et industries culturelles | E35: BPI - Bibliothèque publique d'information | F35: 1 | G35: =H35+I35 -> 61 | H35: 60 | I35: 1 | J35: =K35+L35 -> 60 | K35: 60 | L35: 0 | O35: X
A36: =_xlfn.XLOOKUP(C36,'Annexe Etat'!$I$2:$I$164,'Annexe Etat'!$H$2:$H$164) -> RA | B36: =_xlfn.XLOOKUP(A36,'Annexe Etat'!$A$2:$A$164,'Annexe Etat'!$B$2:$B$164) -> Recherche et enseignement supérieur | C36: 172 | D36: =_xlfn.XLOOKUP(C36,'Annexe Etat'!$I$2:$I$164,'Annexe Etat'!$J$2:$J$164) -> Recherches scientifiques et technologiques pluridisciplinaires | E36: BRGM - Bureau de recherches géologiques et minières | F36: 1 | G36: =H36+I36 -> 1065 | H36: 965 | I36: 100 | J36: =K36+L36 -> 1087 | K36: 967 | L36: 120 | Q36: X
A37: =_xlfn.XLOOKUP(C37,'Annexe Etat'!$I$2:$I$164,'Annexe Etat'!$H$2:$H$164) -> DB | B37: =_xlfn.XLOOKUP(A37,'Annexe Etat'!$A$2:$A$164,'Annexe Etat'!$B$2:$B$164) -> Économie | C37: 134 | D37: =_xlfn.XLOOKUP(C37,'Annexe Etat'!$I$2:$I$164,'Annexe Etat'!$J$2:$J$164) -> Développement des entreprises et régulations | E37: Business France | F37: 1 | G37: =H37+I37 -> 1418 | H37: 1418 | I37: 0 | J37: =K37+L37 -> 1476 | K37: 1392 | L37: 84 | O37: X
A38: =_xlfn.XLOOKUP(C38,'Annexe Etat'!$I$2:$I$164,'Annexe Etat'!$H$2:$H$164) -> AA | B38: =_xlfn.XLOOKUP(A38,'Annexe Etat'!$A$2:$A$164,'Annexe Etat'!$B$2:$B$164) -> Action extérieure de l'État | C38: 185 | D38: =_xlfn.XLOOKUP(C38,'Annexe Etat'!$I$2:$I$164,'Annexe Etat'!$J$2:$J$164) -> Diplomatie culturelle et d'influence | E38: CAMPUS France | F38: 1 | G38: =H38+I38 -> 258 | H38: 233 | I38: 25 | J38: =K38+L38 -> 258 | K38: 233 | L38: 25 | O38: X
A39: =_xlfn.XLOOKUP(C39,'Annexe Etat'!$I$2:$I$164,'Annexe Etat'!$H$2:$H$164) -> CB | B39: =_xlfn.XLOOKUP(A39,'Annexe Etat'!$A$2:$A$164,'Annexe Etat'!$B$2:$B$164) -> Culture | C39: 175 | D39: =_xlfn.XLOOKUP(C39,'Annexe Etat'!$I$2:$I$164,'Annexe Etat'!$J$2:$J$164) -> Patrimoines | E39: CAPA - Cité de l'architecture et du patrimoine | F39: 1 | G39: =H39+I39 -> 134 | H39: 134 | J39: =K39+L39 -> 135 | K39: 135 | P39: X
A40: =_xlfn.XLOOKUP(C40,'Annexe Etat'!$I$2:$I$164,'Annexe Etat'!$H$2:$H$164) -> RA | B40: =_xlfn.XLOOKUP(A40,'Annexe Etat'!$A$2:$A$164,'Annexe Etat'!$B$2:$B$164) -> Recherche et enseignement supérieur | C40: 172 | D40: =_xlfn.XLOOKUP(C40,'Annexe Etat'!$I$2:$I$164,'Annexe Etat'!$J$2:$J$164) -> Recherches scientifiques et technologiques pluridisciplinaires | E40: CEA - Commissariat à l'énergie atomique et aux énergies alternatives | F40: 1 | G40: =H40+I40 -> 20639 | H40: 17296 | I40: 3343 | J40: =K40+L40 -> 20702 | K40: 17319 | L40: 3383 | Q40: X
A41: =_xlfn.XLOOKUP(C41,'Annexe Etat'!$I$2:$I$164,'Annexe Etat'!$H$2:$H$164) -> TA | B41: =_xlfn.XLOOKUP(A41,'Annexe Etat'!$A$2:$A$164,'Annexe Etat'!$B$2:$B$164) -> Écologie, développement et mobilité durables | C41: 113 | D41: =_xlfn.XLOOKUP(C41,'Annexe Etat'!$I$2:$I$164,'Annexe Etat'!$J$2:$J$164) -> Paysages, eau et biodiversité | E41: CELRL - Conservatoire de l'espace littoral et des rivages lacustres | F41: 1 | G41: =H41+I41 -> 208 | H41: 178 | I41: 30 | J41: =K41+L41 -> 206 | K41: 178 | L41: 28 | N41: X
...

Sheet ODAC-ODAL R
B1: Nb | C1: Opérateur déjà traité | D1: Vente | E1: Suppression | F1: EPIC - musée | G1: EPIC - études | H1: Internalisation
B2: =B4+B726+B752 -> 24000 | C2: =SUMIFS($B6:$B777,C6:C777,"oui") -> 384 | D2: =SUMIFS($B6:$B777,D6:D777,"X") -> 410 | E2: =SUMIFS($B6:$B777,E6:E777,"X") -> 13708 | F2: =SUMIFS($B6:$B777,F6:F777,"X") -> 4 | G2: =SUMIFS($B6:$B777,G6:G777,"X") -> 9172 | H2: =SUMIFS($B6:$B777,H6:H777,"X") -> 317
A4: ODAC 2023 Insee 2025 | B4: =SUM(B6:B724) -> 700 | C4: =SUMIFS($B7:$B724,C7:C724,"oui") -> 372 | D4: =SUMIFS($B7:$B724,D7:D724,"X") -> 63 | E4: =SUMIFS($B7:$B724,E7:E724,"X") -> 217 | F4: =SUMIFS($B7:$B724,F7:F724,"X") -> 4 | G4: =SUMIFS($B7:$B724,G7:G724,"X") -> 32 | H4: =SUMIFS($B7:$B724,H7:H724,"X") -> 12
A6: Fonction 1 : Services généraux des administrations publiques
A7: ADOM l'Agence de l'outre-mer pour la mobilité | B7: 1 | C7: oui
A8: AFA Groupement d'intérêt public Agence française de l'adoption | B8: 1 | H8: X
A9: ANTS Agence nationale des titres sécurisés | B9: 1 | C9: oui
A10: BPI_FSIPME FSI PME Portefeuille | B10: 1 | D10: X
A11: BPI_IC Bpifrance international capital | B11: 1 | D11: X
A12: BPI_PARTICIP Bpifrance Participations | B12: 1 | D12: X
A13: BRGM BRGM (Bureau de recherches géologiques et minières) | B13: 1 | C13: oui
A14: CDAD GIP Conseil départemental de laccès au droit de la Lozère | B14: 1 | E14: X
A15: CDAD GIP Conseil départemental de l'accès au droit de la Réunion | B15: 1 | E15: X
A16: CDAD GIP Conseil départemental de l'accès au droit de l'Hérault | B16: 1 | E16: X
A17: CDAD GIP Conseil départemental de l'accès au droit de Lot-et-Garonne | B17: 1 | E17: X
A18: CDAD GIP Conseil départemental de l'accès au droit de Maine-et-Loire | B18: 1 | E18: X
A19: CDAD GIP Conseil départemental de laccès au droit de Paris | B19: 1 | E19: X
A20: CDAD GIP Conseil départemental de l'accès au droit de Vaucluse | B20: 1 | E20: X
A21: CDAD GIP Conseil départemental de l'accès au droit des Alpes de Haute-Provence | B21: 1 | E21: X
A22: CDAD GIP Conseil départemental de l'accès au droit des Alpes Maritimes | B22: 1 | E22: X
A23: CDAD GIP Conseil Départemental de l'accès au droit des Côtes d'Armor | B23: 1 | E23: X
A24: CDAD GIP Conseil départemental de l'accès au droit du Bas-Rhin | B24: 1 | E24: X
A25: CDAD GIP Conseil départemental de l'accès au droit du Pas-de-Calais | B25: 1 | E25: X
... A99: CDAD Groupement d'intérêt public Conseil départemental de l'accès au droit du Var | B99: 1 | E99: X
A100: CDP Caisse de la dette publique | B100: 1 | H100: X
A101: CINES Centre informatique national de l'enseignement supérieur | B101: 1 | C101: oui
A102: CIVIQUE Groupement d'intérêt public Agence du service civique | B102: 1 | C102: oui
A103: CNG Centre national de gestion des praticiens hospitaliers et des personnels de direction de la fonction publique hospitalière | B103: 1 | E103: X
A104: CNRS Centre national de la recherche scientifique | B104: 1 | C104: oui
A105: COFRANCE Collège de France | B105: 1 | C105: oui
A106: CSA Conseil supérieur de l'audiovisuel | B106: 1 | E106: X
A107: CYCERON centre d'imagerie cérébrale et de recherches en neuroscience | B107: 1 | G107: X
A108: FGAO fonds de garantie des assurances obligatoires de dommage | B108: 1 | H108: X
A109: FGTI fonds de garantie des victimes des actes de terrorisme et d'autres infractions | B109: 1 | H109: X
A110: FSD Fonds de solidarité pour le développement | B110: 1 | E110: X
A111: HONNEUR Grande chancellerie de la Légion dhonneur | B111: 1 | C111: oui
A112: IFRTPE Groupement d'intérêt public Institut polaire français Paul-Emile Victor | B112: 1 | C112: oui
A113: IGNF Institut national de linformation géographique et forestière | B113: 1 | C113: oui
A114: IHESBY institut des hautes études scientifiques de Bures-sur-Yvette | B114: 1 | G114: X
A115: INED Institut national détudes démographiques | B115: 1 | C115: oui
...

Sheet Synthèse ETP
A1: Effectifs physiques de la fonction publique par statut au 31 décembre
A2: en milliers
C3: 2023
A4: Total | B4: Fonctionnaires(4) | C4: 3753.124
B5: Contractuels | C5: 1358.476
B6: Militaires | C6: 313.363
B7: Autres catégories et statuts(3) | C7: 378.899
B8: Total | C8: 5803.862
A9: FPE | B9: Fonctionnaires | C9: 1504.471
B10: Contractuels | C10: 582.699
B11: Militaires(2) | C11: 313.363
B12: Autres catégories et statuts(3) | C12: 169.704
B13: Total | C13: 2570.237
A14: FPT | B14: Fonctionnaires(4) | C14: 1422.029
B15: Contractuels | C15: 510.159
B16: Autres catégories et statuts(3) | C16: 62.002
B17: Total | C17: 1994.19
A18: FPH(6) | B18: Fonctionnaires | C18: 826.624
B19: Contractuels | C19: 265.618
B20: Autres catégories et statuts(3) | C20: 147.193
B21: Total | C21: 1239.435
A22: (1) Depuis 2005, les élèves de l'École polytechnique apparaissent dans le champ des EPA de la fonction publique de l'État.
A23: (2) Les militaires volontaires sont comptabilisés dans les effectifs de l'État à partir de 2004.
A24: (3) La catégorie "Autres catégories et statuts" recouvre principalement les enseignants et documentalistes des établissements privés sous contrat et les ouvriers d'État dans la FPE, les assistants maternels et familiaux dans la FPT, les médecins dans la FPH et les apprentis dans les trois versants.
A25: (4) Pour respecter le secret statistique, dans la FPT, les militaires (sapeurs-pompiers de Marseille) sont regroupés avec les fonctionnaires.

Sheet FPT
A1: Effectifs physiques de la fonction publique territoriale par statut des agents et type de collectivité au 31 décembre | F1: Effectifs physiques de la fonction publique territoriale par filière au 31 décembre
A2: en milliers | B2: 2023 | F2: en milliers | H2: 2023
A3: Total FPT (collectivités locales + EPA locaux) | B3: 1994.19 | F3: Total FPT | G3: Ensemble | H3: 1994.19
A4: Dont secteur communal(4) | B4: 1537.399 | G4: Administrative | H4: 447.053
A5: Total collectivités territoriales (communes + départements + régions) | B5: 1414.175 | G5: Animation | H5: 153.926
A6: Communes(1) | B6: 1028.952 | G6: Culturelle | H6: 78.478
A7: Départements | B7: 286.368 | G7: Incendie-secours | H7: 43.946
A8: Régions | B8: 98.855 | G8: Médico-sociale | H8: 87.319
A9: Total EPA locaux | B9: 580.015 | G9: Médico-technique | H9: 2.352
A10: Établissements communaux(1) | B10: 105.384 | G10: Sécurité | H10: 27.434
A11: Établissements intercommunaux(1) | B11: 391.844 | G11: Sociale | H11: 172.562
A12: Établissement départementaux | B12: 71.568 | G12: Sportive | H12: 17.762
A13: Autres EPA locaux | B13: 11.219 | G13: Technique | H13: 870.361
A14: (1) Les évolutions concernant les effectifs des communes et des établissements communaux et intercommunaux doivent être interprétées avec précaution compte tenu des possibles modifications (regroupements notamment), en relation avec la mise en place de structures intercommunales. | G14: Hors filière et indéterminée | H14: 92.997
A15: (2) Pour respecter le secret statistique, dans la FPT les militaires (sapeurs pompiers de Marseille) sont regroupés avec les fonctionnaires et les militaires volontaires avec les contractuels. | F15: Collectivités territoriales | G15: Ensemble | H15: 1414.175
A16: (3) Dans la FPT, la catégorie "autres catégories et statuts" recouvre les collaborateurs de cabinet, les assistants maternels et les apprentis. | G16: Administrative | H16: 314.893
A17: (4) Le secteur communal comprend les communes, les établissements communaux et intercommunaux et d'autres EPA locaux tels que les caisses du crédit municipal, les régies, etc. | G17: Animation | H17: 119.71
A18: (5) En 2018, une Collectivité Territoriale Unique a été mise en place à partir de la fusion des deux départements et de la Collectivité Territoriale de Corse. Les évolutions des effectifs des départements et régions s'expliquent en partie par cette mise en place. Les effectifs de cette nouvelle collectivité sont désormais décomptés avec les régions. A périmètre constant, l'évolution des départements serait de 0,0 % et celle des régions de +3,2 %. | G18: Culturelle | H18: 52.308
G19: Incendie-secours | H19: 0.189
G20: Médico-sociale | H20: 49.768
G21: Médico-technique | H21: 1.743
G22: Sécurité | H22: 26.49
G23: Sociale | H23: 105.408
G24: Sportive | H24: 11.079
G25: Technique | H25: 659.429
G26: Hors filière et indéterminée | H26: 73.158
F27: EPA | G27: Ensemble | H27: 580.015
G28: Administrative | H28: 132.16
G29: Animation | H29: 34.216
G30: Culturelle | H30: 26.17
G31: Incendie-secours | H31: 43.757
G32: Médico-sociale | H32: 37.551
G33: Médico-technique | H33: 0.609
G34: Sécurité | H34: 0.944
G35: Sociale | H35: 67.154
G36: Sportive | H36: 6.683
G37: Technique | H37: 210.932
G38: Hors filière et indéterminée | H38: 19.839

Sheet FPH
A1: Effectifs physiques des personnels non médicaux(1) de la fonction publique hospitalière par filière au 31 décembre
A2: en milliers | C2: 2023 | E2: dont | G2: 2023 | I2: dont | K2: 2023 | M2: dont | O2: 2023
A3: Total FPH | B3: Administrative | C3: 120.931 | E3: Hôpitaux | F3: Administrative | G3: 113.401 | I3: Établissements d'hébergement pour personnes âgées (EHPA) | J3: Administrative | K3: 4.766 | M3: Autres établissements médico-sociaux | N3: Administrative | O3: 2.764
B4: Médico-technique | C4: 47.758 | F4: Médico-technique | G4: 47.554 | J4: Médico-technique | K4: 0.182 | N4: Médico-technique | O4: 0.022
B5: Socio-éducative | C5: 30.542 | F5: Socio-éducative | G5: 18.616 | J5: Socio-éducative | K5: 1.619 | N5: Socio-éducative | O5: 10.307
B6: Soignante | C6: 763.474 | F6: Soignante | G6: 674.714 | J6: Soignante | K6: 73.473 | N6: Soignante | O6: 15.287
B7: Technique-ouvrière | C7: 122.969 | F7: Technique-ouvrière | G7: 106.407 | J7: Technique-ouvrière | K7: 10.295 | N7: Technique-ouvrière | O7: 6.267
B8: Hors filières et indéterminée | C8: 11.336 | F8: Hors filières et indéterminée | G8: 8.19 | J8: Hors filières et indéterminée | K8: 0.39 | N8: Hors filières et indéterminée | O8: 2.756
B9: Ensemble | C9: 1097.01 | F9: Ensemble | G9: 968.882 | J9: Ensemble | K9: 90.725 | N9: Ensemble | O9: 37.403
A10: (1) Les personnels non médicaux recouvrent les agents de la FPH hors médecins et internes.

Sheet FPE
A1: Effectifs des départements ministériels par statut et par ministère de tutelle au 31 décembre | H1: Effectifs des ministères par statut au 31 décembre
A2: en milliers | H2: en milliers
B3: 2023 | I3: 2023
B4: Fonctionnaires | C4: Contractuels | D4: Militaires et militaires volontaires | E4: Autres catégories et statuts(1) | F4: Total | I4: Fonctionnaires | J4: Contractuels | K4: Militaires et militaires volontaires | L4: Autres catégories et statuts(1) | M4: Total
A5: Agriculture et alimentation | B5: 22.029 | C5: 18.323 | D5: 0.023 | E5: 5.106 | F5: 45.481 | H5: Agriculture et alimentation | I5: 18.967 | J5: 5.519 | K5: 0.023 | L5: 4.879 | M5: 29.388
A6: Armées | B6: 39.321 | C6: 22.479 | D6: 212.292 | E6: 16.039 | F6: 290.131 | H6: Armées | I6: 37.622 | J6: 16.353 | K6: 211.61 | L6: 15.817 | M6: 281.402
A7: Culture | B7: 12.201 | C7: 12.482 | D7: 0.006 | E7: 0.388 | F7: 25.077 | H7: Culture | I7: 7.019 | J7: 1.723 | K7: 0.006 | L7: 0.12 | M7: 8.868
A8: Ministères économiques et financiers | B8: 123.242 | C8: 16.969 | D8: 0.067 | E8: 1.822 | F8: 142.1 | H8: Ministères économiques et financiers | I8: 118.401 | J8: 8.682 | K8: 0.065 | L8: 1.424 | M8: 128.572
A9: Éducation nationale, Jeunesse, Sports, Enseignement supérieur, Recherche et Innovation | B9: 967.412 | C9: 385.997 | D9: 0.089 | E9: 136.523 | F9: 1490.021 | H9: Éducation nationale, Jeunesse, Sports, Enseignement supérieur, Recherche et Innovation | I9: 801.726 | J9: 168.992 | K9: 0.07 | L9: 134.293 | M9: 1105.081
A10: Europe et Affaires étrangères(2) | B10: 3.004 | C10: 0.854 | D10: 0.004 | E10: 0.106 | F10: 3.968 | H10: Europe et Affaires étrangères(2) | I10: 2.834 | J10: 0.802 | K10: 0.004 | L10: 0.104 | M10: 3.744
A11: Intérieur et Outre-mer | B11: 181.356 | C11: 21.338 | D11: 100.413 | E11: 2.886 | F11: 305.993 | H11: Intérieur et Outre-mer | I11: 179.869 | J11: 19.211 | K11: 100.356 | L11: 2.838 | M11: 302.274
A12: Justice | B12: 81.91 | C12: 12.528 | D12: 0.091 | E12: 0.447 | F12: 94.976 | H12: Justice | I12: 79.049 | J12: 12.057 | K12: 0.086 | L12: 0.415 | M12: 91.607
A13: Services du Premier ministre | B13: 6.8 | C13: 4.5 | D13: 0.05 | E13: 0.215 | F13: 11.565 | H13: Services du Premier ministre | I13: 6.414 | J13: 4.322 | K13: 0.047 | L13: 0.204 | M13: 10.987
A14: Ministères sociaux | B14: 16.196 | C14: 75.322 | D14: 0.018 | E14: 2.849 | F14: 94.385 | H14: Ministères sociaux | I14: 10.105 | J14: 3.171 | K14: 0.015 | L14: 0.402 | M14: 13.693
A15: Solidarités et santé | B15: 9.536 | C15: 16.899 | D15: 0.008 | E15: 2.122 | F15: 28.565 | H15: Solidarités et santé | I15: 3.546 | J15: 1.896 | K15: 0.005 | L15: 0.235 | M15: 5.682
A16: Travail | B16: 6.66 | C16: 58.423 | D16: 0.01 | E16: 0.727 | F16: 65.82 | H16: Travail | I16: 6.559 | J16: 1.275 | K16: 0.01 | L16: 0.167 | M16: 8.011
... A19: Total hors enseignants(3) | B19: 739.245 | C19: 512.707 | D19: 313.344 | E19: 31.86 | F19: 1597.156 | H19: Total hors enseignants(3) | I19: 599.108 | J19: 188.289 | K19: 312.544 | L19: 24.72 | M19: 1124.661
A22: Effectifs par statut et par catégorie selon la nature de l'employeur au 31 décembre
A23: en milliers
B24: 2023
B25: Catégorie A | C25: Catégorie B | D25: Catégorie C | E25: Indéterminé | F25: Effectifs physiques
A26: Ministères | B26: 1164.361 | C26: 435.925 | D26: 391.483 | E26: 29.489 | F26: 2021.258
A27: EPA | B27: 245.725 | C27: 168.542 | D27: 105.405 | E27: 29.307 | F27: 548.979
A28: Ensemble FPE | B28: 1410.086 | C28: 604.467 | D28: 496.888 | E28: 58.796 | F28: 2570.237

Sheet Emplois Etat RAP 2024
E1: Emplois rémunérés par le programme | R1: Evolution des emplois à périmètre constant
A2: Nature de la | B2: Budget | C2: Code | D2: Libellé de la mission Libellé du programme | E2: Transferts de gestion (1) | F2: Réalisation (2) | G2: LFI + LFR (3) | H2: Transferts de gestion (4) | I2: Réalisation (5) | J2: Ecart à LFI + LFR après transferts de gestion (5- (3+4) | K2: Mesures de périmètre en LFI (6) | L2: Mesures de transfert en LFI (7) | M2: Corrections techniques (8) | N2: Impact des schémas d'emploi (5-4)-(2-1)-(6+7+8) | O2: dont extension en année pleine des schémas d'emploi | P2: dont impact des schémas d'emploi | R2: Sorties | S2: dont départs en retraite | T2: Mois moyen des sorties | U2: Entrées | V2: dont primo recrutements | W2: Mois moyen des entrées | X2: Shéma d'emplois | Y2: Shéma d'emplois
A3: ligne | D3: Libellé de la catégorie d'emploi | E3: 2023 | F3: 2023 | G3: 2024 | H3: 2024 | I3: 2024 | J3: 2024 | K3: 2024 | L3: 2024 | M3: 2024 | O3: 2023 pour 2024 | P3: 2024 sur 2024 | X3: Réalisation | Y3: Prévision PAP
A4: Budget | B4: BA | D4: Budget annexe | F4: 10693.72 | G4: 10923.42 | I4: 10707.33 | J4: -216.09 | M4: 0.89 | N4: 12.72 | O4: 33.71 | P4: -20 | R4: 528.5 | S4: 313.8 | U4: 536.7 | V4: 363.6 | X4: 8.2 | Y4: 13
A5: Mission | B5: BA | C5: XC | D5: Contrôle et exploitation aériens | F5: 10215 | G5: 10439 | I5: 10251 | J5: -188 | M5: 1.83 | N5: 34.17 | O5: 43.6 | P5: -9 | R5: 407 | S5: 270 | U5: 435 | V5: 281 | X5: 28 | Y5: 28
A6: Programme | B6: BA | C6: 613 | D6: Soutien aux prestations de l'aviation civile | F6: 10215 | G6: 10439 | I6: 10251 | J6: -188 | M6: 1.83 | N6: 34.17 | O6: 43.6 | P6: -9 | R6: 407 | S6: 270 | U6: 435 | V6: 281 | X6: 28 | Y6: 28
A7: Catégorie d'emploi | B7: BA | C7: 613-1200 | D7: Administratifs et cadres | F7: 2743 | G7: 2761 | I7: 2737 | J7: -24 | M7: -22.85 | N7: 16.85 | O7: 18.32 | P7: -1 | R7: 163 | S7: 83 | T7: 6.7 | U7: 174 | V7: 55 | W7: 7.2 | X7: 11 | Y7: 3
A8: Catégorie d'emploi | B8: BA | C8: 613-1201 | D8: Ingénieurs du contrôle de la navigation aérienne | F8: 3936 | G8: 3991 | I8: 3996 | J8: 5 | M8: 21.19 | N8: 38.81 | O8: 5.5 | P8: 33 | R8: 73 | S8: 48 | T8: 7.7 | U8: 138 | V8: 123 | W8: 7.3 | X8: 65 | Y8: 61
A9: Catégorie d'emploi | B9: BA | C9: 613-1202 | D9: Ingénieurs électroniciens des systèmes de sécurité aérienne et techniciens supérieurs des études et de l'exploitation de l'aviation civile | F9: 2990 | G9: 3090 | I9: 2987 | J9: -103 | M9: -1.63 | N9: -1.37 | O9: 27.43 | P9: -29 | R9: 135 | S9: 115 | T9: 6.2 | U9: 108 | V9: 103 | W9: 7.7 | X9: -27 | Y9: -13
A10: Catégorie d'emploi | B10: BA | C10: 613-1203 | D10: Ouvriers et personnels navigants | F10: 546 | G10: 597 | I10: 531 | J10: -66 | M10: 5.12 | N10: -20.12 | O10: -7.65 | P10: -12 | R10: 36 | S10: 24 | T10: 6.3 | U10: 15 | W10: 6.9 | X10: -21 | Y10: -23
A11: Mission | B11: BA | C11: XJ | D11: Publications officielles et information administrative | F11: 478.72 | G11: 484.42 | I11: 456.33 | J11: -28.09 | M11: -0.94 | N11: -21.45 | O11: -9.89 | P11: -11 | R11: 121.5 | S11: 43.8 | U11: 101.7 | V11: 82.6 | X11: -19.8 | Y11: -15
A12: Programme | B12: BA | C12: 624 | D12: Pilotage et ressources humaines | F12: 478.72 | G12: 484.42 | I12: 456.33 | J12: -28.09 | M12: -0.94 | N12: -21.45 | O12: -9.89 | P12: -11 | R12: 121.5 | S12: 43.8 | U12: 101.7 | V12: 82.6 | X12: -19.8 | Y12: -15
A13: Catégorie d'emploi | B13: BA | C13: 624-1205 | D13: Catégorie A+ | F13: 10.07 | G13: 8 | I13: 9.75 | J13: 1.75 | N13: -0.32 | O13: 0.01 | R13: 5 | T13: 6.61 | U13: 4 | V13: 3 | W13: 6 | X13: -1
A14: Catégorie d'emploi | B14: BA | C14: 624-1206 | D14: Catégorie A | F14: 83.97 | G14: 88.92 | I14: 80.9 | J14: -8.02 | M14: -0.39 | N14: -2.68 | O14: -1.16 | P14: -2 | R14: 14.3 | S14: 4 | T14: 7.34 | U14: 8.7 | V14: 4.8 | W14: 5.8 | X14: -5.6 | Y14: 3
A15: Catégorie d'emploi | B15: BA | C15: 624-1207 | D15: Catégorie B | F15: 19.16 | G15: 16.25 | I15: 18.95 | J15: 2.7 | N15: -0.21 | O15: 0.09 | R15: 3.8 | S15: 0.8 | T15: 5.13 | U15: 5 | V15: 4 | W15: 7.73 | X15: 1.2 | Y15: -1
A16: Catégorie d'emploi | B16: BA | C16: 624-1208 | D16: Catégorie C | F16: 38.18 | G16: 44.92 | I16: 32.7 | J16: -12.22 | M16: -0.19 | N16: -5.29 | O16: -0.26 | P16: -5 | R16: 8.2 | S16: 4 | T16: 5.45 | U16: 0.2 | W16: 5.03 | X16: -8 | Y16: -3
A17: Catégorie d'emploi | B17: BA | C17: 624-1209 | D17: Contractuels | F17: 327.34 | G17: 326.33 | I17: 314.03 | J17: -12.3 | M17: -0.36 | N17: -12.95 | O17: -8.57 | P17: -4 | R17: 90.2 | S17: 35 | T17: 7.4 | U17: 83.8 | V17: 70.8 | W17: 7.6 | X17: -6.4 | Y17: -14
A18: Budget | B18: BG | D18: Budget général | E18: -1.16 | F18: 1913776.2 | G18: 1974383.5 | H18: -1.0658141e-14 | I18: 1954922.4 | J18: -19461.18 | K18: 20682 | L18: -125 | M18: 8569.92 | N18: 12018.03 | O18: 11107.7 | P18: 914 | R18: 171922.16 | S18: 40130.14 | U18: 178641.46 | V18: 82330.73 | X18: 6719.3 | Y18: 6681.87
A19: Mission | B19: BG | C19: AA | D19: Action extérieure de l'État | F19: 12113.83 | G19: 12289.37 | H19: 1.42 | I19: 12211.84 | J19: -78.95 | M19: 8.31 | N19: 88.28 | O19: 59.41 | P19: 30 | R19: 3471.8 | S19: 170 | U19: 3621.8 | X19: 150 | Y19: 145.87
A20: Programme | B20: BG | C20: 105 | D20: Action de la France en Europe et dans le monde | F20: 8185.54 | G20: 8214 | H20: -0.58 | I20: 8252.28 | J20: 38.86 | M20: 8.35 | N20: 58.97 | O20: 17.12 | P20: 42 | R20: 2182.33 | S20: 117 | U20: 2295.33 | X20: 113 | Y20: 109.87
A21: Catégorie d'emploi | B21: BG | C21: 105-1101 | D21: Titulaires et CDI en administration centrale | F21: 2079.95 | G21: 2306 | H21: -0.58 | I21: 2099.77 | J21: -205.65 | M21: 8 | N21: 12.4 | O21: 60.37 | P21: -48 | R21: 578.9 | S21: 117 | T21: 7.42 | U21: 574.6 | W21: 8.38 | X21: -4.3 | Y21: 35.87
A22: Catégorie d'emploi | B22: BG | C22: 105-1102 | D22: Titulaires et CDI dans le réseau | F22: 1549.81 | G22: 1576.8 | I22: 1539.13 | J22: -37.67 | M22: 0.35 | N22: -11.03 | O22: -44.81 | P22: 34 | R22: 556.7 | T22: 8.55 | U22: 570.83 | W22: 7.95 | X22: 14.13 | Y22: 54
A23: Catégorie d'emploi | B23: BG | C23: 105-1103 | D23: CDD et volontaires internationaux | F23: 947.76 | G23: 594.2 | I23: 1043.05 | J23: 448.85 | N23: 95.29 | O23: 54.6 | P23: 41 | R23: 724.4 | T23: 7.47 | U23: 827.67 | W23: 7.57 | X23: 103.27 | Y23: 20
A24: Catégorie d'emploi | B24: BG | C24: 105-1104 | D24: Militaires | F24: 641.88 | G24: 640 | I24: 621.49 | J24: -18.51 | N24: -20.39 | O24: -18.55 | P24: -2 | R24: 175.44 | T24: 8.23 | U24: 147.34 | W24: 7.47 | X24: -28.1
A25: Catégorie d'emploi | B25: BG | C25: 105-1105 | D25: Agents de droit local | F25: 2966.14 | G25: 3097 | I25: 2948.84 | J25: -148.16 | N25: -17.3 | O25: -34.49 | P25: 17 | R25: 146.89 | T25: 7.63 | U25: 174.89 | W25: 7.31 | X25: 28
A26: Programme | B26: BG | C26: 185 | D26: Diplomatie culturelle et d'influence | F26: 763.88 | G26: 800.37 | I26: 789.22 | J26: -11.15 | N26: 25.34 | O26: 10.56 | P26: 15 | R26: 263.41 | S26: 4 | U26: 280.41 | X26: 17 | Y26: 16
A27: Catégorie d'emploi | B27: BG | C27: 185-1101 | D27: Titulaires et CDI en administration centrale | F27: 58.06 | G27: 79 | I27: 57.52 | J27: -21.48 | N27: -0.54 | O27: -2.41 | P27: 2 | R27: 19.17 | S27: 4 | T27: 7.73 | U27: 23.17 | W27: 7.67 | X27: 4
A28: Catégorie d'emploi | B28: BG | C28: 185-1102 | D28: Titulaires et CDI dans le réseau | F28: 69.19 | G28: 71.92 | I28: 72.22 | J28: 0.3 | N28: 3.03 | O28: -0.19 | P28: 3 | R28: 23.63 | T28: 8.1 | U28: 31.65 | W28: 8.12 | X28: 8.02 | Y28: 2
A29: Catégorie d'emploi | B29: BG | C29: 185-1103 | D29: CDD et volontaires internationaux | F29: 547.74 | G29: 552.45 | I29: 566.61 | J29: 14.16 | N29: 18.87 | O29: 14.36 | P29: 5 | R29: 203.61 | T29: 7.16 | U29: 211.42 | W29: 7.12 | X29: 7.81 | Y29: 14
A30: Catégorie d'emploi | B30: BG | C30: 185-1105 | D30: Agents de droit local | F30: 88.89 | G30: 97 | I30: 92.87 | J30: -4.13 | N30: 3.98 | O30: -1.2 | P30: 5 | R30: 17 | T30: 9.99 | U30: 14.17 | W30: 5 | X30: -2.83
A31: Programme | B31: BG | C31: 151 | D31: Français à l'étranger et affaires consulaires | F31: 3164.41 | G31: 3275 | H31: 2 | I31: 3170.34 | J31: -106.66 | M31: -0.04 | N31: 3.97 | O31: 31.73 | P31: -27 | R31: 1026.06 | S31: 49 | U31: 1046.06 | X31: 20 | Y31: 20
A32: Catégorie d'emploi | B32: BG | C32: 151-1101 | D32: Titulaires et CDI en administration centrale | F32: 468.06 | G32: 527.54 | H32: 2 | I32: 466.18 | J32: -63.36 | M32: -0.04 | N32: -3.84 | O32: -15.9 | P32: 12 | R32: 128.97 | S32: 49 | T32: 8.52 | U32: 124.58 | W32: 7.2 | X32: -4.39 | Y32: 8
A33: Catégorie d'emploi | B33: BG | C33: 151-1102 | D33: Titulaires et CDI dans le réseau | F33: 1028.68 | G33: 1049 | I33: 1046.98 | J33: -2.02 | N33: 18.3 | O33: 32.3 | P33: -14 | R33: 226.2 | T33: 7.37 | U33: 251.26 | W33: 8.6 | X33: 25.06 | Y33: 11
A34: Catégorie d'emploi | B34: BG | C34: 151-1103 | D34: CDD et volontaires internationaux | F34: 80.46 | G34: 101.46 | I34: 97.49 | J34: -3.97 | N34: 17.03 | O34: 12.39 | P34: 5 | R34: 169.5 | T34: 7.7 | U34: 177.34 | W34: 7.62 | X34: 7.84 | Y34: 1
A35: Catégorie d'emploi | B35: BG | C35: 151-1105 | D35: Agents de droit local | F35: 1587.21 | G35: 1597 | I35: 1559.69 | J35: -37.31 | N35: -27.52 | O35: 2.94 | P35: -30 | R35: 501.39 | T35: 7.69 | U35: 492.88 | W35: 8.34 | X35: -8.51
A36: Mission | B36: BG | C36: AB | D36: Administration générale et territoriale de l'État | E36: 149 | F36: 40586.52 | G36: 40616.01 | H36: 148.67 | I36: 40405.64 | J36: -359.04 | L36: -141 | M36: 39.8 | N36: -79.35 | O36: 232.11 | P36: -312 | R36: 13459.6 | S36: 1209.3 | U36: 13736.3 | V36: 1840.2 | X36: 276.7 | Y36: 361
A37: Programme | B37: BG | C37: 354 | D37: Administration territoriale de l'État | E37: 146 | F37: 29422.65 | G37: 29448.08 | H37: 131.08 | I37: 29201.98 | J37: -377.18 | M37: 5.61 | N37: -211.36 | O37: 125.15 | P37: -337 | R37: 10729.7 | S37: 926.4 | U37: 10886.4 | V37: 587.2 | X37: 156.7 | Y37: 232
A38: Catégorie d'emploi | B38: BG | C38: 354-1160 | D38: Hauts fonctionnaires | F38: 1316.75 | G38: 1394 | I38: 1329.37 | J38: -64.63 | M38: 67.42 | N38: -54.8 | O38: -25.59 | P38: -29 | R38: 336 | S38: 28 | T38: 6.23 | U38: 359 | V38: 22 | W38: 7.64 | X38: 23 | Y38: 86
A39: Catégorie d'emploi | B39: BG | C39: 354-1174 | D39: Personnels administratifs cat A | E39: 119 | F39: 5592 | G39: 5440.43 | H39: 126.04 | I39: 5730.13 | J39: 163.66 | M39: -310.79 | N39: 441.88 | O39: 326.75 | P39: 115 | R39: 1164 | S39: 163.3 | T39: 6.1 | U39: 1515.8 | V39: 111 | W39: 6.79 | X39: 351.8 | Y39: 176
A40: Catégorie d'emploi | B40: BG | C40: 354-1175 | D40: Personnels administratifs cat B | E40: 22 | F40: 7945.9 | G40: 7728.12 | H40: 11.34 | I40: 8110.33 | J40: 370.87 | M40: -131.49 | N40: 306.58 | O40: 316.56 | P40: -10 | R40: 2267.6 | S40: 234.1 | T40: 6.25 | U40: 2501.9 | V40: 184.2 | W40: 6.93 | X40: 234.3 | Y40: 70
...

Sheet Annexe Etat
B1: MISSIONS | J1: PROGRAMMES
A2: AA | B2: Action extérieure de l'État | G2: M | H2: AA | I2: Action extérieure de l'État
A3: AB | B3: Administration générale et territoriale de l'État | G3: P | H3: AA | I3: 105 | J3: Action de la France en Europe et dans le monde
A4: AC | B4: Agriculture, alimentation, forêt et affaires rurales | G4: P | H4: AA | I4: 151 | J4: Français à l'étranger et affaires consulaires
A5: AD | B5: Aide publique au développement | G5: P | H5: AA | I5: 185 | J5: Diplomatie culturelle et d'influence
A6: VA | B6: Cohésion des territoires | G6: M | H6: AB | I6: Administration générale et territoriale de l'État
A7: CA | B7: Conseil et contrôle de l'État | G7: P | H7: AB | I7: 216 | J7: Conduite et pilotage des politiques de l'intérieur
A8: CB | B8: Culture | G8: P | H8: AB | I8: 232 | J8: Vie politique
A9: DA | B9: Défense | G9: P | H9: AB | I9: 354 | J9: Administration territoriale de l'État
A10: DC | B10: Direction de l'action du Gouvernement | G10: M | H10: AC | I10: Agriculture, alimentation, forêt et affaires rurales
A11: TA | B11: Écologie, développement et mobilité durables | G11: P | H11: AC | I11: 149 | J11: Compétitivité et durabilité de l'agriculture, de l'agroalimentaire et de la forêt
A12: DB | B12: Économie | G12: P | H12: AC | I12: 206 | J12: Sécurité et qualité sanitaires de l'alimentation
A13: EC | B13: Enseignement scolaire | G13: P | H13: AC | I13: 215 | J13: Conduite et pilotage des politiques de l'agriculture
A14: GA | B14: Gestion des finances publiques | G14: P | H14: AC | I14: 381 | J14: Allègements du coût du travail en agriculture (TODE-AG)
A15: IA | B15: Immigration, asile et intégration | G15: M | H15: AD | I15: Aide publique au développement
A16: AV | B16: Investir pour la France de 2030 | G16: P | H16: AD | I16: 110 | J16: Aide économique et financière au développement
A17: JA | B17: Justice | G17: P | H17: AD | I17: 209 | J17: Solidarité à l'égard des pays en développement
A18: MA | B18: Médias, livre et industries culturelles | G18: P | H18: AD | I18: 365 | J18: Renforcement des fonds propres de l'Agence française de développement
A19: MB | B19: Monde combattant, mémoire et liens avec la Nation | G19: P | H19: AD | I19: 384 | J19: Fonds de solidarité pour le développement
A20: OA | B20: Outre-mer | G20: M | H20: VA | I20: Cohésion des territoires
A21: RA | B21: Recherche et enseignement supérieur | G21: P | H21: VA | I21: 109 | J21: Aide à l'accès au logement
A22: RB | B22: Régimes sociaux et de retraite | G22: P | H22: VA | I22: 112 | J22: Impulsion et coordination de la politique d'aménagement du territoire
A23: RC | B23: Relations avec les collectivités territoriales | G23: P | H23: VA | I23: 135 | J23: Urbanisme, territoires et amélioration de l'habitat
A24: SA | B24: Santé | G24: P | H24: VA | I24: 147 | J24: Politique de la ville
A25: SB | B25: Sécurités | G25: P | H25: VA | I25: 162 | J25: Interventions territoriales de l'État
A26: SE | B26: Solidarité, insertion et égalité des chances | G26: P | H26: VA | I26: 177 | J26: Hébergement, parcours vers le logement et insertion des personnes vulnérables
A27: SF | B27: Sport, jeunesse et vie associative | G27: M | H27: CA | I27: Conseil et contrôle de l'État
A28: TR | B28: Transformation et fonction publiques | G28: P | H28: CA | I28: 126 | J28: Conseil économique, social et environnemental
A29: TB | B29: Travail, emploi et administration des ministères sociaux | G29: P | H29: CA | I29: 164 | J29: Cour des comptes et autres juridictions financières
A30: XC | B30: Contrôle et exploitation aériens | G30: P | H30: CA | I30: 165 | J30: Conseil d'État et autres juridictions administratives
A31: XJ | B31: Publications officielles et information administrative | G31: M | H31: CB | I31: Culture
A32: YK | B32: Financement des aides aux collectivités pour l'électrification rurale | G32: P | H32: CB | I32: 131 | J32: Création
A33: YB | B33: Gestion du patrimoine immobilier de l'État | G33: P | H33: CB | I33: 175 | J33: Patrimoines
A34: YE | B34: Contrôle de la circulation et du stationnement routiers | G34: P | H34: CB | I34: 224 | J34: Soutien aux politiques du ministère de la culture
A35: YF | B35: Développement agricole et rural | G35: P | H35: CB | I35: 361 | J35: Transmission des savoirs et démocratisation de la culture
A36: ZD | B36: Avances à l'audiovisuel public | G36: M | H36: DA | I36: Défense
G37: P | H37: DA | I37: 144 | J37: Environnement et prospective de la politique de défense
G38: P | H38: DA | I38: 146 | J38: Équipement des forces
G39: P | H39: DA | I39: 178 | J39: Préparation et emploi des forces
G40: P | H40: DA | I40: 212 | J40: Soutien de la politique de la défense
...

Sheet Commissions R
A1: Ministère de rattachement | B1: Instance | C1: Texte institutif | D1: Nombre de membres | E1: Coût de fonctionnement 2022 (k€) | F1: Coût de fonctionnement 2023 (k€) | G1: Coût de fonctionnement 2024 (k€) | H1: Réunions 2022 | I1: Réunions 2023 | J1: Réunions 2024 | K1: Statut au Jaune 2026 | L1: Page du Jaune | M1: Observations du Jaune
A2: Premier ministre | B2: Autorité nationale d'Audit pour les Fonds européens | C2: Article 60 de la Loi n° 2002-1576 du 30 décembre 2002 de finances rectificative pour 2002 Décret n° 2008-548 modifié du 11 juin 2008 relatif à la commission interministérielle de coordination des contrôles portant sur les opérations cofinancées par les fonds européens Décret n°2023- 1067 du 30 novembre 2023 relatif à l'Autorité nationale d'audit pour les Fonds européens. Arrêté du 7 janvier 2009 relatif au fonctionnement, aux moyens et à l'organisation interne de la commission interministérielle de coordination des contrôles | D2: 9 | E2: 15.45 | F2: 14.5 | G2: 13.2 | H2: 6 | I2: 6 | J2: 5 | K2: en vigueur | L2: 4 | M2: En 2024, cinq réunions ont été organisées, complétées par une consultation écrite.
A3: Premier ministre | B3: Comité consultatif national d'éthique du numérique | C3: Décret n° 2024-463 du 23 mai 2024 portant création du Comité consultatif national d'éthique du numérique | D3: 21 | E3: 0 | F3: 0 | G3: 0 | H3: 0 | I3: 0 | J3: 0 | K3: en vigueur | L3: 4 | M3: Le CCNE du numérique est un comité créé en mai 2024. Les membres étant toujours en cours de nomination (excepté le président qui a été nommé en février 2025), il n’a pas encore commencé à fonctionner. Ses dépenses de fonctionnement restent réduites et absorbées par le CCNE santé.
A4: Premier ministre | B4: Comité de suivi des retraites | C4: Articles L .114-4 et R. 114-1 à R.114-6 du code de la sécurité sociale | D4: 5 | E4: 16.4 | F4: 12.39 | G4: 20.84 | H4: 8 | I4: 7 | J4: 7 | K4: en vigueur | L4: 5 | M4: Les cinq membres du CSR ont cessé leurs fonctions le 31 juillet 2024. Le nouveau président a été nommé en avril 2025 et les quatre membres en mai 2025. La hausse des coûts entre 2023 et 2024 s'explique par l’augmentation des membres rémunérés (remise d’un rapport) et par la réduction des surfaces occupées en 2023.
A5: Premier ministre | B5: Comité de surveillance des investissements d'avenir | C5: Loi n° 2010-237 du 9 mars 2010 de finances rectificative pour 2010 Décret n° 2010-80 du 22 janvier 2010 relatif au secrétariat général pour l'investissement Décret n° 2021-9 du 7 janvier 2021 modifiant le décret n° 2010-80 du 22 janvier 2010 | D5: 18 | E5: 0 | F5: 0 | G5: 1.5 | H5: 6 | I5: 26 | J5: 5 | K5: en vigueur | L5: 5 | M5: En 2024, cinq réunions plénières ont été organisées. Chacune d’entre elles a été suivie d’un déjeuner, pour un coût global de 1,5 k€.
A6: Premier ministre | B6: Comité directeur de la certification en sécurité des technologies de l'information | C6: Décret n° 2002-535 du 18 avril 2002 relatif à l'évaluation et à la certification de la sécurité offerte par les produits et les systèmes des technologies de l'information | D6: 11 | E6: 0.64 | F6: 0.64 | G6: 0.64 | H6: 1 | I6: 1 | J6: 1 | K6: en vigueur | L6: 5
A7: Premier ministre | B7: Commission chargée de donner un avis sur certaines opérations relatives aux matériels aéronautiques et aux matériels d'armement complexes | C7: Décret n° 2024-509 du 5 juin 2024 renouvelant la commission consultative chargée de donner un avis sur certaines opérations relatives aux matériels aéronautiques et aux matériels d'armement complexes | D7: 8 | E7: 38.68 | F7: 38.68 | G7: 38.68 | H7: 5 | I7: 5 | J7: 5 | K7: en vigueur | L7: 5
A8: Premier ministre | B8: Commission consultative chargée d'émettre un avis sur les matériels susceptibles de porter atteinte à l'intimité de la vie privée et au secret des correspondances | C8: Décret n° 2024-501 du 3 juin 2024 renouvelant la commission consultative chargée d'émettre un avis sur les matériels susceptibles de porter | D8: 11 | E8: 16.19 | F8: 16.19 | G8: 16.19 | H8: 6 | I8: 6 | J8: 6 | K8: en vigueur | L8: 5
A9: Premier ministre | B9: Commission d'enrichissement de la langue française | C9: Décret n° 96-602 modifié du 3 juillet 1996 relatif à l'enrichissement de la langue française | D9: 19 | E9: 0 | F9: 0 | G9: 0 | H9: 11 | I9: 11 | J9: 11 | K9: en vigueur | L9: 6 | M9: La commission ne supporte pas de coût spécifique.
A10: Premier ministre | B10: Commission du droit local d'Alsace- Moselle | C10: Décret n° 2021-1580 du 7 décembre 2021 relatif à la commission du droit local d'Alsace-Moselle. | D10: 24 | E10: 0 | F10: 0 | G10: 0 | H10: 0 | I10: 0 | J10: 3 | K10: en vigueur | L10: 6 | M10: La commission ne supporte pas de coût spécifique car ses membres exercent leurs missions à titre gratuit. De plus, son fonctionnement est indissociable de celui de la préfecture du Bas-Rhin qui assure son secrétariat.
A11: Premier ministre | B11: Commission interministérielle de défense et de sécurité des secteurs d'activités d'importance vitale | C11: Articles R. 1332-10 à R. 1332-12 du code de la défense | D11: 13 | E11: 2.15 | F11: 2.15 | G11: 2.15 | H11: 2 | I11: 2 | J11: 2 | K11: en vigueur | L11: 6
A12: Premier ministre | B12: Commission interministérielle de la sûreté aérienne | C12: Articles D*. 1443-1 et D.1443-4 du code de la défense | D12: 12 | E12: 5.31 | F12: 5.31 | G12: 2.66 | H12: 2 | I12: 2 | J12: 1 | K12: en vigueur | L12: 6
A13: Premier ministre | B13: Commission interministérielle des biens à double usage | C13: Décret n° 2010-294 du 18 mars 2010 portant création d'une commission interministérielle des biens à double usage ; Décret n° 2020-367 du 26 mars 2020 portant prorogation de la commission interministérielle des biens à double usage ; Décret n° 2023-471 du 19 juin 2023 relatif à la présidence de la commission interministérielle des biens à double usage. | D13: 12 | E13: 0.65 | F13: 0.3 | G13: 0.3 | H13: 12 | I13: 12 | J13: 12 | K13: en vigueur | L13: 6
A14: Premier ministre | B14: Commission interministérielle pour l'étude des exportations de matériels de guerre | C14: Article D. 1132-53 du code de la défense Décret n° 55- 965 du 16 juillet 1955 portant réorganisation de la commission | D14: 12 | E14: 1255.13 | F14: 1255.13 | G14: 1255.13 | H14: 11 | I14: 11 | J14: 11 | K14: en vigueur | L14: 6
A15: Premier ministre | B15: Commission nationale consultative des gens du voyage | C15: Article 10-1 de la loi n° 2000-614 du 5 juillet 2000 relative à l’accueil et à l’habitat des gens du voyage Décret n° 2015-563 du 20 mai 2015 relatif à la Commission nationale consultative des gens du voyage | D15: 33 | E15: 6.35 | F15: 7.07 | G15: 6.4 | H15: 7 | I15: 15 | J15: 14 | K15: en vigueur | L15: 7 | M15: En 2024, la Commission a été très active, avec plusieurs réunions plénières (5 janvier, 27 mars, 26 juin, 23 octobre) et de nombreux groupes de travail, notamment sur le projet mémoriel de Montreuil-Bellay (7 réunions) et sur les difficultés de stationnement (2 réunions en janvier et mars, co-présidé par le ministère de l’Intérieur). Les frais engagés concernent principalement le transport et la restauration du Président et de certains membres lors des réunions, ainsi que des déplacements conjoints du Président avec la Dihal (Perpignan, Tours, Angers) et des rendez-vous avec des cabinets ministériels ou groupes de travail délocalisés. Par ailleurs, un travail préparatoire a été mené pour améliorer le fonctionnement de la Commission en vue de la nouvelle mandature qui débutera en 2026.
A16: Premier ministre | B16: Commission nationale d'orientation et d'intégration | C16: Articles R.* 4139-14 et suivants du code de la défense | D16: 5 | E16: 0 | F16: 0 | G16: 0 | H16: 10 | I16: 10 | J16: 8 | K16: en vigueur | L16: 8
A17: Premier ministre | B17: Commission nationale des professions foraines et circassiennes | C17: Décret n°2017-1501 du 27 octobre 2017 relatif à la Commission nationale des professions foraines et circassiennes Décret n°2023-7 du 6 janvier 2023 modifiant le décret n° 2017-1501 du 27 octobre 2017 | D17: 24 | E17: 7.6 | F17: 6.6 | G17: 7.8 | H17: 3 | I17: 3 | J17: 3 | K17: en vigueur | L17: 8 | M17: La légère évolution du budget de fonctionnement de la Commission est liée à la création de la cellule d'accompagnement individualisée à destination des circassiens, dans le cadre de l'application de la loi n° 2021-1536 du 30 novembre 2021.
A18: Premier ministre | B18: Commission pour la restitution des biens et l'indemnisation des victimes de spoliations antisémites (CIVS) | C18: Décret n° 2024-11 du 5 janvier 2024 instituant une commission pour la restitution des biens et l'indemnisation des victimes de spoliations antisémites et pris en application des articles L. 115-3, L. 115-4 et L. 451-10-1 du code du patrimoine | D18: 14 | E18: 134.67 | F18: 126.75 | G18: 116.47 | H18: 15 | I18: 17 | J18: 15 | K18: en vigueur | L18: 8 | M18: Les coûts de fonctionnement de la commission peuvent varier en fonction du taux de présence en réunion et du calendrier de tenue des réunions.
